#!/usr/bin/env python3
from mcpi.minecraft import Minecraft
from mcpi import block

###########################################################
#
# Initialise the Village. A clearing is made in front of the player.
# A road is placed along the z axis with grass either side of it.
# The Minecraft connection is returned.
#
###########################################################
def init():
    mc = Minecraft.create()
    x, y, z = mc.player.getTilePos()
    if z > 70:
        # We need room along the z axis for the steet
        z = 9999
    mc.setBlocks(x-15, -1, z-2, x+15, 50, z+58, block.AIR.id)
    mc.setBlocks(x-9999, -0.7, z-9999, x+9999, -0.7, z+9999, block.WATER.id)
    mc.setBlocks(x-9999, -0.0, z-9999, x+9999, -0.0, z+9999, block.ICE.id)
    mc.player.setPos(x, 0, z)
    return mc

###########################################################
#
# Construct a House centered on coordinates x, y, z.
# The house is 6 blocks deep and 7 blocks wide.
#
###########################################################
def makeHouse(mc, x, y, z):
    # Build the shell
    mc.setBlocks(x-2, y, z-3, x+3, y+2, z+3, block.ICE.id)
    mc.setBlocks(x-1, y, z-2, x+2, y+2, z+2, block.WATER.id)

    # Add the roof
    mc.setBlocks(x-2, y+3, z-3, x-2, y+3, z+3, block.ICE.id, 0)
    mc.setBlocks(x+3, y+3, z-3, x+3, y+3, z+3, block.ICE.id, 1)
    mc.setBlocks(x-1, y+4, z-3, x-1, y+4, z+3, block.ICE.id, 0)
    mc.setBlocks(x+2, y+4, z-3, x+2, y+4, z+3, block.ICE.id, 1)
    mc.setBlocks(x, y+5, z-3, x, y+5, z+3, block.ICE.id, 0)
    mc.setBlocks(x+1, y+5, z-3, x+1, y+5, z+3, block.ICE.id, 1)

    # Fill in each end of the roof
    mc.setBlocks(x-1, y+3, z-3, x+2, y+3, z-3, block.ICE.id)
    mc.setBlocks(x, y+4, z-3, x+1, y+4, z-3, block.ICE.id)
    mc.setBlocks(x-1, y+3, z+3, x+2, y+3, z+3, block.ICE.id)
    mc.setBlocks(x, y+4, z+3, x+1, y+4, z+3, block.ICE.id)
    
    # Add doors front and rear and pathways
    mc.setBlock(x-2, y, z-1, block.AIR.id, 0)
    mc.setBlock(x-2, y+1, z-1, block.AIR.id, 8)
    mc.setBlock(x+3, y, z+1, block.AIR.id, 2)
    mc.setBlock(x+3, y+1, z+1, block.AIR.id, 10)
    mc.setBlocks(x-3, y-1, z-1, x-4, y-1, z-1, block.ICE.id)
    mc.setBlocks(x+4, y-1, z+1, x+5, y-1, z+1, block.ICE.id)

    # Add Windows
    mc.setBlocks(x-2, y+1, z, x-2, y+1, z+1, block.FENCE.id)
    mc.setBlocks(x+3, y+1, z, x+3, y+1, z-1, block.FENCE.id)
    mc.setBlocks(x, y+1, z-3, x+1, y+1, z-3, block.FENCE.id)
    mc.setBlocks(x, y+1, z+3, x+1, y+1, z+3, block.FENCE.id)
    
#def makeHouse(mc, x, y, z):
	# Build the shell
    mc.setBlocks(x-4, y, z-6, x+6, y+4, z+6, block.LAVA.id)
    mc.setBlocks(x-2, y, z-4, x+4, y+4, z+4, block.WATER.id)

    # Add the roof
    mc.setBlocks(x-4, y+6, z-6, x-4, y+6, z+6, block.GLOWING_OBSIDIAN.id, 0)
    mc.setBlocks(x+6, y+6, z-6, x+6, y+6, z+6, block.GLOWING_OBSIDIAN.id, 1)
    mc.setBlocks(x-4, y+8, z-6, x-2, y+8, z+6, block.GLOWING_OBSIDIAN.id, 0)
    mc.setBlocks(x+4, y+8, z-6, x+4, y+8, z+6, block.GLOWING_OBSIDIAN.id, 1)
    mc.setBlocks(x, y+10, z-6, x, y+10, z+6, block.GLOWING_OBSIDIAN.id, 0)
    mc.setBlocks(x+2, y+10, z-6, x+2, y+10, z+6, block.GLOWING_OBSIDIAN.id, 1)

    # Fill in each end of the roof
    mc.setBlocks(x-2, y+6, z-6, x+4, y+6, z-6, block.GLOWING_OBSIDIAN.id)
    mc.setBlocks(x, y+8, z-6, x+2, y+8, z-6, block.GLOWING_OBSIDIAN.id)
    mc.setBlocks(x-2, y+6, z+6, x+4, y+6, z+6, block.GLOWING_OBSIDIAN.id)
    mc.setBlocks(x, y+8, z+6, x+2, y+8, z+6, block.GLOWING_OBSIDIAN.id)
    
    # Add doors front and rear and pathways
    mc.setBlock(x-4, y, z-2, block.AIR.id, 0)
    mc.setBlock(x-4, y+2, z-2, block.AIR.id, 8)
    mc.setBlock(x+6, y, z+2, block.AIR.id, 2)
    mc.setBlock(x+6, y+2, z+2, block.AIR.id, 10)
    mc.setBlocks(x-6, y-2, z-2, x-8, y-2, z-2, block.GLOWING_OBSIDIAN.id)
    mc.setBlocks(x+8, y-2, z+2, x+10, y-2, z+2, block.GLOWING_OBSIDIAN.id)

    # Add Windows
    mc.setBlocks(x-4, y+2, z, x-4, y+2, z+2, block.FENCE_GATE.id)
    mc.setBlocks(x+6, y+2, z, x+6, y+2, z-2, block.FENCE_GATE.id)
    mc.setBlocks(x, y+2, z-6, x+2, y+2, z-6, block.FENCE_GATE.id)
    mc.setBlocks(x, y+2, z+6, x+2, y+2, z+6, block.FENCE_GATE.id)
    



mc = init()
x, y, z = mc.player.getTilePos()
makeHouse(mc, x+7, y, z+4)
makeHouse(mc, x+17, y, z+14)

##################################################
#
#  Exercises:
#
# 1. Run this code and explore the world in Minecraft, see the road
#    and the house that have been built.
#
# 2. Make a copy of the above line of code "makeHouse..." and
#    change it so that a second house is build on the other side of the road.
#    Hint: You will have to change the location of the new house.
#
# 3. Wrap both of the "makeHouse..." lines in a for loop to create 
#    a row of houses along each side of the road. You should be able to make
#    6 houses spaced 10 blocks apart. You will have to change the arguments
#    supplied to both "makeHouse..." calls so that the houses are built
#    all along the road. Refer to last week's "Steps" exercise for an
#    example of building things inside a for loop.
#
# 4. Copy and Paste the whole "makeHouse..." function and change the name
#    of it to something else (for example "makeShop"). Now change the code
#    inside the copied function so that it creates your new design (for
#    example, a shop will have large windows, a pavement all the way across
#    the front and an awning.
#
# 5. Change your for loop so that is uses both "makeHouse" and "makeShop"
#    (for example the houses on one side of the street and the shops on the
#    other).
#
#  Code source: http://www.cotswoldjam.org/downloads/2017-01/minecraft-village/village.py
